[2025-04-01T12:09:51.446+0000] {local_task_job_runner.py:123} INFO - ::group::Pre task execution logs
[2025-04-01T12:09:51.467+0000] {taskinstance.py:2614} INFO - Dependencies all met for dep_context=non-requeueable deps ti=<TaskInstance: youtube_etl_dag.load_data_to_s3 manual__2025-04-01T12:08:54.598679+00:00 [queued]>
[2025-04-01T12:09:51.482+0000] {taskinstance.py:2614} INFO - Dependencies all met for dep_context=requeueable deps ti=<TaskInstance: youtube_etl_dag.load_data_to_s3 manual__2025-04-01T12:08:54.598679+00:00 [queued]>
[2025-04-01T12:09:51.483+0000] {taskinstance.py:2867} INFO - Starting attempt 1 of 1
[2025-04-01T12:09:51.518+0000] {taskinstance.py:2890} INFO - Executing <Task(PythonOperator): load_data_to_s3> on 2025-04-01 12:08:54.598679+00:00
[2025-04-01T12:09:51.531+0000] {standard_task_runner.py:104} INFO - Running: ['airflow', 'tasks', 'run', 'youtube_etl_dag', 'load_data_to_s3', 'manual__2025-04-01T12:08:54.598679+00:00', '--job-id', '60', '--raw', '--subdir', 'DAGS_FOLDER/youtube_etl_dag.py', '--cfg-path', '/tmp/tmpok3ll44t']
[2025-04-01T12:09:51.533+0000] {standard_task_runner.py:105} INFO - Job 60: Subtask load_data_to_s3
[2025-04-01T12:09:51.535+0000] {logging_mixin.py:190} WARNING - /home/airflow/.local/lib/python3.12/site-packages/airflow/task/task_runner/standard_task_runner.py:70 DeprecationWarning: This process (pid=2147) is multi-threaded, use of fork() may lead to deadlocks in the child.
[2025-04-01T12:09:51.536+0000] {standard_task_runner.py:72} INFO - Started process 2157 to run task
[2025-04-01T12:09:51.635+0000] {task_command.py:467} INFO - Running <TaskInstance: youtube_etl_dag.load_data_to_s3 manual__2025-04-01T12:08:54.598679+00:00 [running]> on host 5d58ffcd3aee
[2025-04-01T12:09:51.800+0000] {taskinstance.py:3134} INFO - Exporting env vars: AIRFLOW_CTX_DAG_OWNER='airflow' AIRFLOW_CTX_DAG_ID='youtube_etl_dag' AIRFLOW_CTX_TASK_ID='load_data_to_s3' AIRFLOW_CTX_EXECUTION_DATE='2025-04-01T12:08:54.598679+00:00' AIRFLOW_CTX_TRY_NUMBER='1' AIRFLOW_CTX_DAG_RUN_ID='manual__2025-04-01T12:08:54.598679+00:00'
[2025-04-01T12:09:51.801+0000] {taskinstance.py:732} INFO - ::endgroup::
[2025-04-01T12:09:52.348+0000] {youtube_etl_dag.py:154} INFO - Uploading /opt/airflow/Transformed_Youtube_Data_2025-04-01/part-00000-5ab39761-e4c2-4f10-a887-6465f2b93f31-c000.csv to S3://tb-dataengineeringproject-ytdata-2025/processed-data/2025-04-01/part-00000-5ab39761-e4c2-4f10-a887-6465f2b93f31-c000.csv
[2025-04-01T12:09:55.188+0000] {taskinstance.py:3313} ERROR - Task failed with exception
Traceback (most recent call last):
  File "/home/airflow/.local/lib/python3.12/site-packages/boto3/s3/transfer.py", line 372, in upload_file
    future.result()
  File "/home/airflow/.local/lib/python3.12/site-packages/s3transfer/futures.py", line 103, in result
    return self._coordinator.result()
           ^^^^^^^^^^^^^^^^^^^^^^^^^^
  File "/home/airflow/.local/lib/python3.12/site-packages/s3transfer/futures.py", line 264, in result
    raise self._exception
  File "/home/airflow/.local/lib/python3.12/site-packages/s3transfer/tasks.py", line 135, in __call__
    return self._execute_main(kwargs)
           ^^^^^^^^^^^^^^^^^^^^^^^^^^
  File "/home/airflow/.local/lib/python3.12/site-packages/s3transfer/tasks.py", line 158, in _execute_main
    return_value = self._main(**kwargs)
                   ^^^^^^^^^^^^^^^^^^^^
  File "/home/airflow/.local/lib/python3.12/site-packages/s3transfer/upload.py", line 796, in _main
    client.put_object(Bucket=bucket, Key=key, Body=body, **extra_args)
  File "/home/airflow/.local/lib/python3.12/site-packages/botocore/client.py", line 569, in _api_call
    return self._make_api_call(operation_name, kwargs)
           ^^^^^^^^^^^^^^^^^^^^^^^^^^^^^^^^^^^^^^^^^^^
  File "/home/airflow/.local/lib/python3.12/site-packages/botocore/client.py", line 1023, in _make_api_call
    raise error_class(parsed_response, operation_name)
botocore.exceptions.ClientError: An error occurred (AccessDenied) when calling the PutObject operation: User: arn:aws:iam::767828725836:user/YT_Trend is not authorized to perform: s3:PutObject on resource: "arn:aws:s3:::tb-dataengineeringproject-ytdata-2025/processed-data/2025-04-01/part-00000-5ab39761-e4c2-4f10-a887-6465f2b93f31-c000.csv" because no identity-based policy allows the s3:PutObject action

During handling of the above exception, another exception occurred:

Traceback (most recent call last):
  File "/home/airflow/.local/lib/python3.12/site-packages/airflow/models/taskinstance.py", line 768, in _execute_task
    result = _execute_callable(context=context, **execute_callable_kwargs)
             ^^^^^^^^^^^^^^^^^^^^^^^^^^^^^^^^^^^^^^^^^^^^^^^^^^^^^^^^^^^^^
  File "/home/airflow/.local/lib/python3.12/site-packages/airflow/models/taskinstance.py", line 734, in _execute_callable
    return ExecutionCallableRunner(
           ^^^^^^^^^^^^^^^^^^^^^^^^
  File "/home/airflow/.local/lib/python3.12/site-packages/airflow/utils/operator_helpers.py", line 252, in run
    return self.func(*args, **kwargs)
           ^^^^^^^^^^^^^^^^^^^^^^^^^^
  File "/home/airflow/.local/lib/python3.12/site-packages/airflow/models/baseoperator.py", line 424, in wrapper
    return func(self, *args, **kwargs)
           ^^^^^^^^^^^^^^^^^^^^^^^^^^^
  File "/home/airflow/.local/lib/python3.12/site-packages/airflow/operators/python.py", line 238, in execute
    return_value = self.execute_callable()
                   ^^^^^^^^^^^^^^^^^^^^^^^
  File "/home/airflow/.local/lib/python3.12/site-packages/airflow/operators/python.py", line 256, in execute_callable
    return runner.run(*self.op_args, **self.op_kwargs)
           ^^^^^^^^^^^^^^^^^^^^^^^^^^^^^^^^^^^^^^^^^^^
  File "/home/airflow/.local/lib/python3.12/site-packages/airflow/utils/operator_helpers.py", line 252, in run
    return self.func(*args, **kwargs)
           ^^^^^^^^^^^^^^^^^^^^^^^^^^
  File "/opt/airflow/dags/youtube_etl_dag.py", line 138, in load_data_to_s3
    upload_to_s3(bucket_name,prefix,local_dir_path)
  File "/opt/airflow/dags/youtube_etl_dag.py", line 155, in upload_to_s3
    s3_client.upload_file(file_path, bucket_name, s3_key)
  File "/home/airflow/.local/lib/python3.12/site-packages/boto3/s3/inject.py", line 145, in upload_file
    return transfer.upload_file(
           ^^^^^^^^^^^^^^^^^^^^^
  File "/home/airflow/.local/lib/python3.12/site-packages/boto3/s3/transfer.py", line 378, in upload_file
    raise S3UploadFailedError(
boto3.exceptions.S3UploadFailedError: Failed to upload /opt/airflow/Transformed_Youtube_Data_2025-04-01/part-00000-5ab39761-e4c2-4f10-a887-6465f2b93f31-c000.csv to tb-dataengineeringproject-ytdata-2025/processed-data/2025-04-01/part-00000-5ab39761-e4c2-4f10-a887-6465f2b93f31-c000.csv: An error occurred (AccessDenied) when calling the PutObject operation: User: arn:aws:iam::767828725836:user/YT_Trend is not authorized to perform: s3:PutObject on resource: "arn:aws:s3:::tb-dataengineeringproject-ytdata-2025/processed-data/2025-04-01/part-00000-5ab39761-e4c2-4f10-a887-6465f2b93f31-c000.csv" because no identity-based policy allows the s3:PutObject action
[2025-04-01T12:09:55.210+0000] {taskinstance.py:1226} INFO - Marking task as FAILED. dag_id=youtube_etl_dag, task_id=load_data_to_s3, run_id=manual__2025-04-01T12:08:54.598679+00:00, execution_date=20250401T120854, start_date=20250401T120951, end_date=20250401T120955
[2025-04-01T12:09:55.289+0000] {taskinstance.py:341} INFO - ::group::Post task execution logs
[2025-04-01T12:09:55.291+0000] {standard_task_runner.py:124} ERROR - Failed to execute job 60 for task load_data_to_s3 (Failed to upload /opt/airflow/Transformed_Youtube_Data_2025-04-01/part-00000-5ab39761-e4c2-4f10-a887-6465f2b93f31-c000.csv to tb-dataengineeringproject-ytdata-2025/processed-data/2025-04-01/part-00000-5ab39761-e4c2-4f10-a887-6465f2b93f31-c000.csv: An error occurred (AccessDenied) when calling the PutObject operation: User: arn:aws:iam::767828725836:user/YT_Trend is not authorized to perform: s3:PutObject on resource: "arn:aws:s3:::tb-dataengineeringproject-ytdata-2025/processed-data/2025-04-01/part-00000-5ab39761-e4c2-4f10-a887-6465f2b93f31-c000.csv" because no identity-based policy allows the s3:PutObject action; 2157)
Traceback (most recent call last):
  File "/home/airflow/.local/lib/python3.12/site-packages/boto3/s3/transfer.py", line 372, in upload_file
    future.result()
  File "/home/airflow/.local/lib/python3.12/site-packages/s3transfer/futures.py", line 103, in result
    return self._coordinator.result()
           ^^^^^^^^^^^^^^^^^^^^^^^^^^
  File "/home/airflow/.local/lib/python3.12/site-packages/s3transfer/futures.py", line 264, in result
    raise self._exception
  File "/home/airflow/.local/lib/python3.12/site-packages/s3transfer/tasks.py", line 135, in __call__
    return self._execute_main(kwargs)
           ^^^^^^^^^^^^^^^^^^^^^^^^^^
  File "/home/airflow/.local/lib/python3.12/site-packages/s3transfer/tasks.py", line 158, in _execute_main
    return_value = self._main(**kwargs)
                   ^^^^^^^^^^^^^^^^^^^^
  File "/home/airflow/.local/lib/python3.12/site-packages/s3transfer/upload.py", line 796, in _main
    client.put_object(Bucket=bucket, Key=key, Body=body, **extra_args)
  File "/home/airflow/.local/lib/python3.12/site-packages/botocore/client.py", line 569, in _api_call
    return self._make_api_call(operation_name, kwargs)
           ^^^^^^^^^^^^^^^^^^^^^^^^^^^^^^^^^^^^^^^^^^^
  File "/home/airflow/.local/lib/python3.12/site-packages/botocore/client.py", line 1023, in _make_api_call
    raise error_class(parsed_response, operation_name)
botocore.exceptions.ClientError: An error occurred (AccessDenied) when calling the PutObject operation: User: arn:aws:iam::767828725836:user/YT_Trend is not authorized to perform: s3:PutObject on resource: "arn:aws:s3:::tb-dataengineeringproject-ytdata-2025/processed-data/2025-04-01/part-00000-5ab39761-e4c2-4f10-a887-6465f2b93f31-c000.csv" because no identity-based policy allows the s3:PutObject action

During handling of the above exception, another exception occurred:

Traceback (most recent call last):
  File "/home/airflow/.local/lib/python3.12/site-packages/airflow/task/task_runner/standard_task_runner.py", line 117, in _start_by_fork
    ret = args.func(args, dag=self.dag)
          ^^^^^^^^^^^^^^^^^^^^^^^^^^^^^
  File "/home/airflow/.local/lib/python3.12/site-packages/airflow/cli/cli_config.py", line 49, in command
    return func(*args, **kwargs)
           ^^^^^^^^^^^^^^^^^^^^^
  File "/home/airflow/.local/lib/python3.12/site-packages/airflow/utils/cli.py", line 116, in wrapper
    return f(*args, **kwargs)
           ^^^^^^^^^^^^^^^^^^
  File "/home/airflow/.local/lib/python3.12/site-packages/airflow/cli/commands/task_command.py", line 483, in task_run
    task_return_code = _run_task_by_selected_method(args, _dag, ti)
                       ^^^^^^^^^^^^^^^^^^^^^^^^^^^^^^^^^^^^^^^^^^^^
  File "/home/airflow/.local/lib/python3.12/site-packages/airflow/cli/commands/task_command.py", line 256, in _run_task_by_selected_method
    return _run_raw_task(args, ti)
           ^^^^^^^^^^^^^^^^^^^^^^^
  File "/home/airflow/.local/lib/python3.12/site-packages/airflow/cli/commands/task_command.py", line 341, in _run_raw_task
    return ti._run_raw_task(
           ^^^^^^^^^^^^^^^^^
  File "/home/airflow/.local/lib/python3.12/site-packages/airflow/utils/session.py", line 97, in wrapper
    return func(*args, session=session, **kwargs)
           ^^^^^^^^^^^^^^^^^^^^^^^^^^^^^^^^^^^^^^
  File "/home/airflow/.local/lib/python3.12/site-packages/airflow/models/taskinstance.py", line 3006, in _run_raw_task
    return _run_raw_task(
           ^^^^^^^^^^^^^^
  File "/home/airflow/.local/lib/python3.12/site-packages/airflow/models/taskinstance.py", line 274, in _run_raw_task
    TaskInstance._execute_task_with_callbacks(
  File "/home/airflow/.local/lib/python3.12/site-packages/airflow/models/taskinstance.py", line 3161, in _execute_task_with_callbacks
    result = self._execute_task(context, task_orig)
             ^^^^^^^^^^^^^^^^^^^^^^^^^^^^^^^^^^^^^^
  File "/home/airflow/.local/lib/python3.12/site-packages/airflow/models/taskinstance.py", line 3185, in _execute_task
    return _execute_task(self, context, task_orig)
           ^^^^^^^^^^^^^^^^^^^^^^^^^^^^^^^^^^^^^^^
  File "/home/airflow/.local/lib/python3.12/site-packages/airflow/models/taskinstance.py", line 768, in _execute_task
    result = _execute_callable(context=context, **execute_callable_kwargs)
             ^^^^^^^^^^^^^^^^^^^^^^^^^^^^^^^^^^^^^^^^^^^^^^^^^^^^^^^^^^^^^
  File "/home/airflow/.local/lib/python3.12/site-packages/airflow/models/taskinstance.py", line 734, in _execute_callable
    return ExecutionCallableRunner(
           ^^^^^^^^^^^^^^^^^^^^^^^^
  File "/home/airflow/.local/lib/python3.12/site-packages/airflow/utils/operator_helpers.py", line 252, in run
    return self.func(*args, **kwargs)
           ^^^^^^^^^^^^^^^^^^^^^^^^^^
  File "/home/airflow/.local/lib/python3.12/site-packages/airflow/models/baseoperator.py", line 424, in wrapper
    return func(self, *args, **kwargs)
           ^^^^^^^^^^^^^^^^^^^^^^^^^^^
  File "/home/airflow/.local/lib/python3.12/site-packages/airflow/operators/python.py", line 238, in execute
    return_value = self.execute_callable()
                   ^^^^^^^^^^^^^^^^^^^^^^^
  File "/home/airflow/.local/lib/python3.12/site-packages/airflow/operators/python.py", line 256, in execute_callable
    return runner.run(*self.op_args, **self.op_kwargs)
           ^^^^^^^^^^^^^^^^^^^^^^^^^^^^^^^^^^^^^^^^^^^
  File "/home/airflow/.local/lib/python3.12/site-packages/airflow/utils/operator_helpers.py", line 252, in run
    return self.func(*args, **kwargs)
           ^^^^^^^^^^^^^^^^^^^^^^^^^^
  File "/opt/airflow/dags/youtube_etl_dag.py", line 138, in load_data_to_s3
    upload_to_s3(bucket_name,prefix,local_dir_path)
  File "/opt/airflow/dags/youtube_etl_dag.py", line 155, in upload_to_s3
    s3_client.upload_file(file_path, bucket_name, s3_key)
  File "/home/airflow/.local/lib/python3.12/site-packages/boto3/s3/inject.py", line 145, in upload_file
    return transfer.upload_file(
           ^^^^^^^^^^^^^^^^^^^^^
  File "/home/airflow/.local/lib/python3.12/site-packages/boto3/s3/transfer.py", line 378, in upload_file
    raise S3UploadFailedError(
boto3.exceptions.S3UploadFailedError: Failed to upload /opt/airflow/Transformed_Youtube_Data_2025-04-01/part-00000-5ab39761-e4c2-4f10-a887-6465f2b93f31-c000.csv to tb-dataengineeringproject-ytdata-2025/processed-data/2025-04-01/part-00000-5ab39761-e4c2-4f10-a887-6465f2b93f31-c000.csv: An error occurred (AccessDenied) when calling the PutObject operation: User: arn:aws:iam::767828725836:user/YT_Trend is not authorized to perform: s3:PutObject on resource: "arn:aws:s3:::tb-dataengineeringproject-ytdata-2025/processed-data/2025-04-01/part-00000-5ab39761-e4c2-4f10-a887-6465f2b93f31-c000.csv" because no identity-based policy allows the s3:PutObject action
[2025-04-01T12:09:55.342+0000] {local_task_job_runner.py:266} INFO - Task exited with return code 1
[2025-04-01T12:09:55.476+0000] {taskinstance.py:3901} INFO - 0 downstream tasks scheduled from follow-on schedule check
[2025-04-01T12:09:55.482+0000] {local_task_job_runner.py:245} INFO - ::endgroup::
